import os
from datetime import datetime, timedelta
from typing import Annotated

from fastapi import Depends, HTTPException, status
from fastapi.security import OAuth2PasswordBearer
from jose import JWTError, jwt
from passlib.context import CryptContext

from backend.schemas.user_schema import TokenData, UserResponse
from backend.database import get_db
from backend.models.user_model import User
from sqlalchemy.orm import Session

SECRET_KEY = os.getenv("SECRET_KEY", "7347264762764762")
ALGORITHM = "HS256"
ACCESS_TOKEN_EXPIRE_MINUTES = 30

oauth2_scheme = OAuth2PasswordBearer(tokenUrl="users/token")

pwd_context = CryptContext(schemes=["bcrypt"], deprecated="auto")

def verify_password(plain_password: str, hashed_password: str) -> bool:
    return pwd_context.verify(plain_password, hashed_password)

def get_password_hash(password: str) -> str:
    return pwd_context.hash(password)

def create_access_token(data: dict, expires_delta: timedelta | None = None) -> str:
    to_encode = data.copy()
    if expires_delta:
        expire = datetime.utcnow() + expires_delta
    else:
        expire = datetime.utcnow() + timedelta(minutes=ACCESS_TOKEN_EXPIRE_MINUTES)
    to_encode.update({"exp": expire})
    encoded_jwt = jwt.encode(to_encode, SECRET_KEY, algorithm=ALGORITHM)
    return encoded_jwt

async def get_current_user(token: Annotated[str, Depends(oauth2_scheme)], db: Session = Depends(get_db)):
    credentials_exception = HTTPException(
        status_code=status.HTTP_401_UNAUTHORIZED,
        detail="Não foi possível validar as credenciais",
        headers={"WWW-Authenticate": "Bearer"},
    )
    try:
        payload = jwt.decode(token, SECRET_KEY, algorithms=[ALGORITHM])
        username: str = payload.get("sub")
        if username is None:
            raise credentials_exception
        token_data = TokenData(username=username)
    except JWTError:
        raise credentials_exception
    
    user = db.query(User).filter(User.username == token_data.username).first()
    if user is None:
        raise credentials_exception
    return UserResponse.model_validate(user)
